<?xml version="1.0" encoding="UTF-8"?>
<!-- Generated by org.testng.reporters.JUnitReportReporter -->
<testsuite hostname="DESKTOP-L3R1A1J" name="com.mycompanyTest.TestProject.TestDemo" tests="4" failures="1" timestamp="30 Dec 2021 03:21:14 GMT" time="0.082" errors="0">
  <testcase name="test1" time="0.056" classname="com.mycompanyTest.TestProject.TestDemo"/>
  <testcase name="test3" time="0.003" classname="com.mycompanyTest.TestProject.TestDemo"/>
  <testcase name="test2" time="0.021" classname="com.mycompanyTest.TestProject.TestDemo">
    <failure type="java.lang.AssertionError" message="expected [true] but found [false]">
      <![CDATA[java.lang.AssertionError: expected [true] but found [false]
	at org.testng.Assert.fail(Assert.java:94)
	at org.testng.Assert.failNotEquals(Assert.java:513)
	at org.testng.Assert.assertTrue(Assert.java:42)
	at org.testng.Assert.assertTrue(Assert.java:52)
	at com.mycompanyTest.TestProject.TestDemo.test2(TestDemo.java:23)
	at sun.reflect.NativeMethodAccessorImpl.invoke0(Native Method)
	at sun.reflect.NativeMethodAccessorImpl.invoke(Unknown Source)
	at sun.reflect.DelegatingMethodAccessorImpl.invoke(Unknown Source)
	at java.lang.reflect.Method.invoke(Unknown Source)
	at org.testng.internal.MethodInvocationHelper.invokeMethod(MethodInvocationHelper.java:100)
	at org.testng.internal.Invoker.invokeMethod(Invoker.java:646)
	at org.testng.internal.Invoker.invokeTestMethod(Invoker.java:811)
	at org.testng.internal.Invoker.invokeTestMethods(Invoker.java:1129)
	at org.testng.internal.TestMethodWorker.invokeTestMethods(TestMethodWorker.java:129)
	at org.testng.internal.TestMethodWorker.run(TestMethodWorker.java:112)
	at org.testng.TestRunner.privateRun(TestRunner.java:746)
	at org.testng.TestRunner.run(TestRunner.java:600)
	at org.testng.SuiteRunner.runTest(SuiteRunner.java:366)
	at org.testng.SuiteRunner.runSequentially(SuiteRunner.java:361)
	at org.testng.SuiteRunner.privateRun(SuiteRunner.java:319)
	at org.testng.SuiteRunner.run(SuiteRunner.java:268)
	at org.testng.SuiteRunnerWorker.runSuite(SuiteRunnerWorker.java:52)
	at org.testng.SuiteRunnerWorker.run(SuiteRunnerWorker.java:86)
	at org.testng.TestNG.runSuitesSequentially(TestNG.java:1264)
	at org.testng.TestNG.runSuitesLocally(TestNG.java:1189)
	at org.testng.TestNG.runSuites(TestNG.java:1104)
	at org.testng.TestNG.run(TestNG.java:1076)
	at org.testng.remote.AbstractRemoteTestNG.run(AbstractRemoteTestNG.java:126)
	at org.testng.remote.RemoteTestNG.initAndRun(RemoteTestNG.java:152)
	at org.testng.remote.RemoteTestNG.main(RemoteTestNG.java:57)
]]>
    </failure>
  </testcase> <!-- test2 -->
  <testcase name="test4" time="0.002" classname="com.mycompanyTest.TestProject.TestDemo"/>
</testsuite> <!-- com.mycompanyTest.TestProject.TestDemo -->
